Workbook

Sheet FMM
H15: 45077
A20: Registered Name: | B20: Cara Mia Sales and Services Inc. | H20: WH/OUT/31096, WH/OUT/31034
A22: TIN: | B22: 009-062-877
A24: Business Address: | B24: 101 Connecticut cor Missouri St. Greenhills San Juan
A26: ITEM CODE | B26: ITEM DESCRIPTION
A27: FM1120 | B27: =VLOOKUP(A27,'ITEM LIST'!A:D,3,FALSE) -> MIDNIGHT DREAM CAKE, WHOLE, MINI | E27: 4 | F27: =VLOOKUP(A27,'ITEM LIST'!A:D,4,FALSE) -> PC | G27: 1303.75 | H27: 1460.2
A28: FM1333 | B28: =VLOOKUP(A28,'ITEM LIST'!A:D,3,FALSE) -> COFFEE CRUNCH, 70 G/PK, PK | E28: 10 | F28: =VLOOKUP(A28,'ITEM LIST'!A:D,4,FALSE) -> PK | G28: 119 | H28: 133.28
A29: FM1293 | B29: =VLOOKUP(A29,'ITEM LIST'!A:D,3,FALSE) -> SALTED CHOCOLATE SMORES CAKE, NEW, PC | E29: 10 | F29: =VLOOKUP(A29,'ITEM LIST'!A:D,4,FALSE) -> PC | G29: 4571.875 | H29: 5120.5
A30: FM1281 | B30: =VLOOKUP(A30,'ITEM LIST'!A:D,3,FALSE) -> MINI MANGO MAGNIFICO, PC | E30: 4 | F30: =VLOOKUP(A30,'ITEM LIST'!A:D,4,FALSE) -> PC | G30: 1303.75 | H30: 1460.2
A31: FM1175 | B31: =VLOOKUP(A31,'ITEM LIST'!A:D,3,FALSE) -> UBE CAKE, PC | E31: 29 | F31: =VLOOKUP(A31,'ITEM LIST'!A:D,4,FALSE) -> PC | G31: 13258.437 | H31: 14849.45
A32: FM1118 | B32: =VLOOKUP(A32,'ITEM LIST'!A:D,3,FALSE) -> CASHEW BRITTLE, 10 GRAMS PER PACK | E32: 4 | F32: =VLOOKUP(A32,'ITEM LIST'!A:D,4,FALSE) -> PK | G32: 14.023207 | H32: 15.705992
A33: FM1116 | B33: =VLOOKUP(A33,'ITEM LIST'!A:D,3,FALSE) -> STRAWBERRY CAKE, PIECE | E33: 5 | F33: =VLOOKUP(A33,'ITEM LIST'!A:D,4,FALSE) -> PC | G33: 3051.5625 | H33: 3417.75
A34: FM1212 | B34: =VLOOKUP(A34,'ITEM LIST'!A:D,3,FALSE) -> STRAWBERRY, VACUUM PACKED, PK | E34: 5 | F34: =VLOOKUP(A34,'ITEM LIST'!A:D,4,FALSE) -> PK | G34: 528.86828 | H34: 592.33247
A35: FM0594 | B35: =VLOOKUP(A35,'ITEM LIST'!A:D,3,FALSE) -> SEA SALTED HONEY CRUNCH CAKE | E35: 10 | F35: =VLOOKUP(A35,'ITEM LIST'!A:D,4,FALSE) -> PC | G35: 3784.375 | H35: 4238.5
A36: FM0846 | B36: =VLOOKUP(A36,'ITEM LIST'!A:D,3,FALSE) -> SEA SALTED CRUNCH 140 GM | E36: 10 | F36: =VLOOKUP(A36,'ITEM LIST'!A:D,4,FALSE) -> PK | G36: 131.33 | H36: 147.0896
A37: FM0375 | B37: =VLOOKUP(A37,'ITEM LIST'!A:D,3,FALSE) -> PIPING CHOCOLATE, 200G/PK | E37: 3 | F37: =VLOOKUP(A37,'ITEM LIST'!A:D,4,FALSE) -> PK | G37: 138.02782 | H37: 154.59116
A38: FM0376 | B38: =VLOOKUP(A38,'ITEM LIST'!A:D,3,FALSE) -> BLANK HAPPY BIRTHDAY LABEL, 24PCS/BX | E38: 4 | F38: =VLOOKUP(A38,'ITEM LIST'!A:D,4,FALSE) -> BX | G38: 621.98453 | H38: 696.62267
... A66: FM0565 | B66: =VLOOKUP(A66,'ITEM LIST'!A:D,3,FALSE) -> MIDNIGHT DREAM CAKE, PC | E66: 6 | F66: =VLOOKUP(A66,'ITEM LIST'!A:D,4,FALSE) -> PC | G66: 2795.625 | H66: 3131.1
B70: Branch: FMM
B72: Week: 5/1/2023
B74: Superceeds Invoice NO: 6533
F75: Total Sales (VAT Incluive) | H75: =SUM(H27:H73) -> 93238.201
H77: 9989.8072
A79: Vatables Sales | H79: =H75-H77 -> 83248.394
A80: VAT
A81: Zero-Rated Sales | F81: =H79 -> 83248.394
A82: VAT-Excempt Sales
F83: =H77 -> 9989.8072 | H83: =F83 -> 9989.8072
H84: =F81*0.01 -> 832.48394
H85: =(H79+H83)-H84 -> 92405.717

Sheet FMM (2)
H15: 45077
A20: Registered Name: | B20: Cara Mia Sales and Services Inc. | H20: WH/OUT/31544, WH/OUT/31512, WH/OUT/31538, WH/OUT/31398, WH/OUT/31492
A22: TIN: | B22: 009-062-877
A24: Business Address: | B24: 101 Connecticut cor Missouri St. Greenhills San Juan
A26: ITEM CODE | B26: ITEM DESCRIPTION
A27: FM1333 | B27: =VLOOKUP(A27,'ITEM LIST'!A:D,3,FALSE) -> COFFEE CRUNCH, 70 G/PK, PK | E27: 8 | F27: =VLOOKUP(A27,'ITEM LIST'!A:D,4,FALSE) -> PK | G27: 95.2 | H27: 106.624
A28: FM1293 | B28: =VLOOKUP(A28,'ITEM LIST'!A:D,3,FALSE) -> SALTED CHOCOLATE SMORES CAKE, NEW, PC | E28: 4 | F28: =VLOOKUP(A28,'ITEM LIST'!A:D,4,FALSE) -> PC | G28: 1828.75 | H28: 2048.2
A29: FM1281 | B29: =VLOOKUP(A29,'ITEM LIST'!A:D,3,FALSE) -> MINI MANGO MAGNIFICO, PC | E29: 4 | F29: =VLOOKUP(A29,'ITEM LIST'!A:D,4,FALSE) -> PC | G29: 1303.75 | H29: 1460.2
A30: FM1223 | B30: =VLOOKUP(A30,'ITEM LIST'!A:D,3,FALSE) -> MANGO MAGNIFICO CAKE, WHOLE, NEW DESIGN | E30: 8 | F30: =VLOOKUP(A30,'ITEM LIST'!A:D,4,FALSE) -> PC | G30: 3657.5 | H30: 4096.4
A31: FM0846 | B31: =VLOOKUP(A31,'ITEM LIST'!A:D,3,FALSE) -> SEA SALTED CRUNCH 140 GM | E31: 8 | F31: =VLOOKUP(A31,'ITEM LIST'!A:D,4,FALSE) -> PK | G31: 105.064 | H31: 117.67168
A32: FM0565 | B32: =VLOOKUP(A32,'ITEM LIST'!A:D,3,FALSE) -> MIDNIGHT DREAM CAKE, PC | E32: 8 | F32: =VLOOKUP(A32,'ITEM LIST'!A:D,4,FALSE) -> PC | G32: 3727.5 | H32: 4174.8
A33: PM0074 | B33: =VLOOKUP(A33,'ITEM LIST'!A:D,3,FALSE) -> RIBBON,YELLOW,#5 CUT EDGE RIBBON, 50YARDS/RL, RL | E33: 20 | F33: =VLOOKUP(A33,'ITEM LIST'!A:D,4,FALSE) -> RL | G33: 1273.28 | H33: 1426.0736
A34: PM0186 | B34: =VLOOKUP(A34,'ITEM LIST'!A:D,3,FALSE) -> STICKER, CARAMIA HEART-SHAPE W/ PLASTIC LAM, 1.45”x1.75” | E34: 504 | F34: =VLOOKUP(A34,'ITEM LIST'!A:D,4,FALSE) -> PC | G34: 931.5 | H34: 1043.28
A35: PM0176 | B35: =VLOOKUP(A35,'ITEM LIST'!A:D,3,FALSE) -> STICKER, GELATO PINT W/ PRINT, COLD ADHESION | E35: 27 | F35: =VLOOKUP(A35,'ITEM LIST'!A:D,4,FALSE) -> SET | G35: 263.37045 | H35: 294.9749
A36: PM0174 | B36: =VLOOKUP(A36,'ITEM LIST'!A:D,3,FALSE) -> Plastic, Tub & Lid, Gelato, Pint | E36: 27 | F36: =VLOOKUP(A36,'ITEM LIST'!A:D,4,FALSE) -> SET | G36: 291.249 | H36: 326.19888
A37: PM0158 | B37: =VLOOKUP(A37,'ITEM LIST'!A:D,3,FALSE) -> PAPER, BAG, KRAFT#2, CARAMIA, 70GSM | E37: 80 | F37: =VLOOKUP(A37,'ITEM LIST'!A:D,4,FALSE) -> PC | G37: 381.8 | H37: 427.616
A38: FM0365 | B38: =VLOOKUP(A38,'ITEM LIST'!A:D,3,FALSE) -> STRAWBERRY FROZEN, 150G / PACK | E38: 5 | F38: =VLOOKUP(A38,'ITEM LIST'!A:D,4,FALSE) -> PK | G38: 177.9 | H38: 199.248
... A66: RM0002 | B66: =VLOOKUP(A66,'ITEM LIST'!A:D,3,FALSE) -> BISCUIT COOKIES, VANILLA, 12/274GM, KG | E66: 0.239 | F66: =VLOOKUP(A66,'ITEM LIST'!A:D,4,FALSE) -> KG | G66: 79.124535 | H66: 88.619479
B70: Branch: FMM
B72: Week: 5/1/2023
B74: Superceeds Invoice NO: 6533
F75: Total Sales (VAT Incluive) | H75: =SUM(H27:H73) -> 65926.693
H77: 7063.5742
A79: Vatables Sales | H79: =H75-H77 -> 58863.118
A80: VAT
A81: Zero-Rated Sales | F81: =H79 -> 58863.118
A82: VAT-Excempt Sales
F83: =H77 -> 7063.5742 | H83: =F83 -> 7063.5742
H84: =F81*0.01 -> 588.63118
H85: =(H79+H83)-H84 -> 65338.062

Sheet FMM (3)
H15: 45077
A20: Registered Name: | B20: Cara Mia Sales and Services Inc. | H20: WH/OUT/31544, WH/OUT/31568, WH/OUT/31729, WH/OUT/31752, WH/OUT/31721
A22: TIN: | B22: 009-062-877
A24: Business Address: | B24: 101 Connecticut cor Missouri St. Greenhills San Juan
A26: ITEM CODE | B26: ITEM DESCRIPTION
A27: CM0020 | B27: =VLOOKUP(A27,'ITEM LIST'!A:D,3,FALSE) -> CLEANING, LIQUID HAND SOAP,10 X 500ML/CS, L | E27: 3.78 | F27: =VLOOKUP(A27,'ITEM LIST'!A:D,4,FALSE) -> LT | G27: 307.63719 | H27: 344.55365
A28: FM0374 | B28: =VLOOKUP(A28,'ITEM LIST'!A:D,3,FALSE) -> HAPPY BIRTHDAY LABEL, 24PCS/BOX | E28: 2 | F28: =VLOOKUP(A28,'ITEM LIST'!A:D,4,FALSE) -> BX | G28: 326.42122 | H28: 365.59176
A29: FM1334 | B29: =VLOOKUP(A29,'ITEM LIST'!A:D,3,FALSE) -> CHOCOLATE JAVA CAKE, PC | E29: 15 | F29: =VLOOKUP(A29,'ITEM LIST'!A:D,4,FALSE) -> PC | G29: 6529.6875 | H29: 7313.25
A30: FM1293 | B30: =VLOOKUP(A30,'ITEM LIST'!A:D,3,FALSE) -> SALTED CHOCOLATE SMORES CAKE, NEW, PC | E30: 15 | F30: =VLOOKUP(A30,'ITEM LIST'!A:D,4,FALSE) -> PC | G30: 6857.8125 | H30: 7680.75
A31: FM1223 | B31: =VLOOKUP(A31,'ITEM LIST'!A:D,3,FALSE) -> MANGO MAGNIFICO CAKE, WHOLE, NEW DESIGN | E31: 18 | F31: =VLOOKUP(A31,'ITEM LIST'!A:D,4,FALSE) -> PC | G31: 8229.375 | H31: 9216.9
A32: FM1175 | B32: =VLOOKUP(A32,'ITEM LIST'!A:D,3,FALSE) -> UBE CAKE, PC | E32: 35 | F32: =VLOOKUP(A32,'ITEM LIST'!A:D,4,FALSE) -> PC | G32: 16001.562 | H32: 17921.75
A33: FM1212 | B33: =VLOOKUP(A33,'ITEM LIST'!A:D,3,FALSE) -> STRAWBERRY, VACUUM PACKED, PK | E33: 4 | F33: =VLOOKUP(A33,'ITEM LIST'!A:D,4,FALSE) -> PK | G33: 423.09462 | H33: 473.86598
A34: FM1116 | B34: =VLOOKUP(A34,'ITEM LIST'!A:D,3,FALSE) -> STRAWBERRY CAKE, PIECE | E34: 4 | F34: =VLOOKUP(A34,'ITEM LIST'!A:D,4,FALSE) -> PC | G34: 2441.25 | H34: 2734.2
A35: FM0846 | B35: =VLOOKUP(A35,'ITEM LIST'!A:D,3,FALSE) -> SEA SALTED CRUNCH 140 GM | E35: 15 | F35: =VLOOKUP(A35,'ITEM LIST'!A:D,4,FALSE) -> PK | G35: 196.995 | H35: 220.6344
A36: FM0594 | B36: =VLOOKUP(A36,'ITEM LIST'!A:D,3,FALSE) -> SEA SALTED HONEY CRUNCH CAKE | E36: 15 | F36: =VLOOKUP(A36,'ITEM LIST'!A:D,4,FALSE) -> PC | G36: 5676.5625 | H36: 6357.75
A37: FM0566 | B37: =VLOOKUP(A37,'ITEM LIST'!A:D,3,FALSE) -> CASHEW BRITTLE, 15G/PK, PK | E37: 16 | F37: =VLOOKUP(A37,'ITEM LIST'!A:D,4,FALSE) -> PK | G37: 84.139241 | H37: 94.23595
A38: FM0565 | B38: =VLOOKUP(A38,'ITEM LIST'!A:D,3,FALSE) -> MIDNIGHT DREAM CAKE, PC | E38: 16 | F38: =VLOOKUP(A38,'ITEM LIST'!A:D,4,FALSE) -> PC | G38: 7455 | H38: 8349.6
... A66: RM0002 | B66: =VLOOKUP(A66,'ITEM LIST'!A:D,3,FALSE) -> BISCUIT COOKIES, VANILLA, 12/274GM, KG | E66: 0.239 | F66: =VLOOKUP(A66,'ITEM LIST'!A:D,4,FALSE) -> KG | G66: 79.124535 | H66: 88.619479
B70: Branch: FMM
B72: Week: 5/1/2023
B74: Superceeds Invoice NO: 6533
F75: Total Sales (VAT Incluive) | H75: =SUM(H27:H73) -> 94940.765
H77: 10172.225
A79: Vatables Sales | H79: =H75-H77 -> 84768.54
A80: VAT
A81: Zero-Rated Sales | F81: =H79 -> 84768.54
A82: VAT-Excempt Sales
F83: =H77 -> 10172.225 | H83: =F83 -> 10172.225
H84: =F81*0.01 -> 847.6854
H85: =(H79+H83)-H84 -> 94093.08

Sheet FMM (4)
H15: 45077
A20: Registered Name: | B20: Cara Mia Sales and Services Inc. | H20: WH/OUT/32202, WH/OUT/32086, WH/OUT/32121, WH/OUT/31568
A22: TIN: | B22: 009-062-877
A24: Business Address: | B24: 101 Connecticut cor Missouri St. Greenhills San Juan
A26: ITEM CODE | B26: ITEM DESCRIPTION
A27: PM0113 | B27: =VLOOKUP(A27,'ITEM LIST'!A:D,3,FALSE) -> THERMAL BAG,PINK&SILVER,W/PRINT, 10.5X10.5X6in, | E27: 25 | F27: =VLOOKUP(A27,'ITEM LIST'!A:D,4,FALSE) -> PC | G27: 3465.525 | H27: 3881.388
A28: PM0137 | B28: =VLOOKUP(A28,'ITEM LIST'!A:D,3,FALSE) -> DISPOSABLE PAPER CUP ,PRINTED 3OZ, 2PE-180GSM | E28: 200 | F28: =VLOOKUP(A28,'ITEM LIST'!A:D,4,FALSE) -> PC | G28: 204.7 | H28: 229.264
A29: PM0190 | B29: =VLOOKUP(A29,'ITEM LIST'!A:D,3,FALSE) -> INSULATED FOAM, POUCH, PINT, 8x10”x 5in (overlap) | E29: 50 | F29: =VLOOKUP(A29,'ITEM LIST'!A:D,4,FALSE) -> PC | G29: 346.725 | H29: 388.332
A30: PM0174 | B30: =VLOOKUP(A30,'ITEM LIST'!A:D,3,FALSE) -> Plastic, Tub & Lid, Gelato, Pint | E30: 27 | F30: =VLOOKUP(A30,'ITEM LIST'!A:D,4,FALSE) -> SET | G30: 291.249 | H30: 326.19888
A31: PM0158 | B31: =VLOOKUP(A31,'ITEM LIST'!A:D,3,FALSE) -> PAPER, BAG, KRAFT#2, CARAMIA, 70GSM | E31: 80 | F31: =VLOOKUP(A31,'ITEM LIST'!A:D,4,FALSE) -> PC | G31: 381.8 | H31: 427.616
A32: CM0057 | B32: =VLOOKUP(A32,'ITEM LIST'!A:D,3,FALSE) -> WHITE PAPER, HAND TOWEL 200X200MM,1PLY,150 PCS/PCK, 30PCKS/CASE | E32: 30 | F32: =VLOOKUP(A32,'ITEM LIST'!A:D,4,FALSE) -> PK | G32: 883.13839 | H32: 989.115
A33: CM0003 | B33: =VLOOKUP(A33,'ITEM LIST'!A:D,3,FALSE) -> DISPOSABLE, PLASTIC GLOVES, LARGE, 100 PCS XPACK | E33: 15 | F33: =VLOOKUP(A33,'ITEM LIST'!A:D,4,FALSE) -> PK | G33: 770.04 | H33: 862.4448
A34: CM0001 | B34: =VLOOKUP(A34,'ITEM LIST'!A:D,3,FALSE) -> CLING WRAP, 30 METERS PER ROLL | E34: 2 | F34: =VLOOKUP(A34,'ITEM LIST'!A:D,4,FALSE) -> RL | G34: 492.867 | H34: 552.01104
A35: CM0044 | B35: =VLOOKUP(A35,'ITEM LIST'!A:D,3,FALSE) -> NAPKIN, TABLE,WHT, BEST CHOICE, 5PK/CS | E35: 4 | F35: =VLOOKUP(A35,'ITEM LIST'!A:D,4,FALSE) -> PK | G35: 205.35714 | H35: 230
A36: RM0002 | B36: =VLOOKUP(A36,'ITEM LIST'!A:D,3,FALSE) -> BISCUIT COOKIES, VANILLA, 12/274GM, KG | E36: 1.914 | F36: =VLOOKUP(A36,'ITEM LIST'!A:D,4,FALSE) -> KG | G36: 633.65841 | H36: 709.69742
A37: CM0130 | B37: =VLOOKUP(A37,'ITEM LIST'!A:D,3,FALSE) -> GENUINE EPSON BRAND ERC-38 RIBBON, BLACK | E37: 10 | F37: =VLOOKUP(A37,'ITEM LIST'!A:D,4,FALSE) -> PC | G37: 1488.8393 | H37: 1667.5
A38: FM1333 | B38: =VLOOKUP(A38,'ITEM LIST'!A:D,3,FALSE) -> COFFEE CRUNCH, 70 G/PK, PK | E38: 20 | F38: =VLOOKUP(A38,'ITEM LIST'!A:D,4,FALSE) -> PK | G38: 238 | H38: 266.56
... A66: FM1333 | B66: =VLOOKUP(A66,'ITEM LIST'!A:D,3,FALSE) -> COFFEE CRUNCH, 70 G/PK, PK | E66: 40 | F66: =VLOOKUP(A66,'ITEM LIST'!A:D,4,FALSE) -> PK | G66: 476 | H66: 533.12
B70: Branch: FMM
B72: Week: 5/1/2023
B74: Superceeds Invoice NO: 6533
F75: Total Sales (VAT Incluive) | H75: =SUM(H27:H73) -> 305286.72
H77: 32709.291
A79: Vatables Sales | H79: =H75-H77 -> 272577.43
A80: VAT
A81: Zero-Rated Sales | F81: =H79 -> 272577.43
A82: VAT-Excempt Sales
F83: =H77 -> 32709.291 | H83: =F83 -> 32709.291
H84: =F81*0.01 -> 2725.7743
H85: =(H79+H83)-H84 -> 302560.94

Sheet FMM (5)
H15: 45077
A20: Registered Name: | B20: Cara Mia Sales and Services Inc. | H20: WH/OUT/32384, WH/OUT/32295, WH/OUT/32254, WH/OUT/32264, WH/OUT/32167, WH/OUT/32202, WH/OUT/32356
A22: TIN: | B22: 009-062-877
A24: Business Address: | B24: 101 Connecticut cor Missouri St. Greenhills San Juan
A26: ITEM CODE | B26: ITEM DESCRIPTION
A27: FM1334 | B27: =VLOOKUP(A27,'ITEM LIST'!A:D,3,FALSE) -> CHOCOLATE JAVA CAKE, PC | E27: 40 | F27: =VLOOKUP(A27,'ITEM LIST'!A:D,4,FALSE) -> PC | G27: 17412.5 | H27: 19502
A28: FM0846 | B28: =VLOOKUP(A28,'ITEM LIST'!A:D,3,FALSE) -> SEA SALTED CRUNCH 140 GM | E28: 40 | F28: =VLOOKUP(A28,'ITEM LIST'!A:D,4,FALSE) -> PK | G28: 525.32 | H28: 588.3584
A29: FM0565 | B29: =VLOOKUP(A29,'ITEM LIST'!A:D,3,FALSE) -> MIDNIGHT DREAM CAKE, PC | E29: 28 | F29: =VLOOKUP(A29,'ITEM LIST'!A:D,4,FALSE) -> PC | G29: 13046.25 | H29: 14611.8
A30: FM0827 | B30: =VLOOKUP(A30,'ITEM LIST'!A:D,3,FALSE) -> OREO COOKIES N' CREAM, 4.5KG./TRAY | E30: 1 | F30: =VLOOKUP(A30,'ITEM LIST'!A:D,4,FALSE) -> TR | G30: 2362.5 | H30: 2646
A31: FM0822 | B31: =VLOOKUP(A31,'ITEM LIST'!A:D,3,FALSE) -> CHOCOLATE THERAPY GELATO, 4.5/TRAY | E31: 0.56 | F31: =VLOOKUP(A31,'ITEM LIST'!A:D,4,FALSE) -> TR | G31: 1323 | H31: 1481.76
A32: FM0819 | B32: =VLOOKUP(A32,'ITEM LIST'!A:D,3,FALSE) -> STRAWBERRY GELATO, 2.5 KG TRAY | E32: 1 | F32: =VLOOKUP(A32,'ITEM LIST'!A:D,4,FALSE) -> TR | G32: 1312.5 | H32: 1470
A33: FM0642 | B33: =VLOOKUP(A33,'ITEM LIST'!A:D,3,FALSE) -> TURTLE PIE, 2.5KG/TRAY | E33: 1 | F33: =VLOOKUP(A33,'ITEM LIST'!A:D,4,FALSE) -> TR | G33: 1312.5 | H33: 1470
A34: FM0324 | B34: =VLOOKUP(A34,'ITEM LIST'!A:D,3,FALSE) -> NEW FERRERO, 2.5KG/TRAY | E34: 1 | F34: =VLOOKUP(A34,'ITEM LIST'!A:D,4,FALSE) -> TR | G34: 1312.5 | H34: 1470
A35: FM1205 | B35: =VLOOKUP(A35,'ITEM LIST'!A:D,3,FALSE) -> UBE GELATO, 2.5 KG/TRAY | E35: 1 | F35: =VLOOKUP(A35,'ITEM LIST'!A:D,4,FALSE) -> TR | G35: 1312.5 | H35: 1470
A36: FM1214 | B36: =VLOOKUP(A36,'ITEM LIST'!A:D,3,FALSE) -> RED GLAZE, 100G/PK | E36: 1 | F36: =VLOOKUP(A36,'ITEM LIST'!A:D,4,FALSE) -> PK | G36: 23.470077 | H36: 26.286486
A37: FM0376 | B37: =VLOOKUP(A37,'ITEM LIST'!A:D,3,FALSE) -> BLANK HAPPY BIRTHDAY LABEL, 24PCS/BX | E37: 6 | F37: =VLOOKUP(A37,'ITEM LIST'!A:D,4,FALSE) -> BX | G37: 932.97679 | H37: 1044.934
A38: FM0375 | B38: =VLOOKUP(A38,'ITEM LIST'!A:D,3,FALSE) -> PIPING CHOCOLATE, 200G/PK | E38: 4 | F38: =VLOOKUP(A38,'ITEM LIST'!A:D,4,FALSE) -> PK | G38: 184.03709 | H38: 206.12155
... A66: FM0324 | B66: =VLOOKUP(A66,'ITEM LIST'!A:D,3,FALSE) -> NEW FERRERO, 2.5KG/TRAY | E66: 1 | F66: =VLOOKUP(A66,'ITEM LIST'!A:D,4,FALSE) -> TR | G66: 1312.5 | H66: 1470
B70: Branch: FMM
B72: Week: 5/1/2023
B74: Superceeds Invoice NO: 6533
F75: Total Sales (VAT Incluive) | H75: =SUM(H27:H73) -> 114158.64
H77: 12231.283
A79: Vatables Sales | H79: =H75-H77 -> 101927.36
A80: VAT
A81: Zero-Rated Sales | F81: =H79 -> 101927.36
A82: VAT-Excempt Sales
F83: =H77 -> 12231.283 | H83: =F83 -> 12231.283
H84: =F81*0.01 -> 1019.2736
H85: =(H79+H83)-H84 -> 113139.37

Sheet FMM (6)
H15: 45077
A20: Registered Name: | B20: Cara Mia Sales and Services Inc. | H20: WH/OUT/32636, WH/OUT/32413, WH/OUT/32384
A22: TIN: | B22: 009-062-877
A24: Business Address: | B24: 101 Connecticut cor Missouri St. Greenhills San Juan
A26: ITEM CODE | B26: ITEM DESCRIPTION
A27: FM0326 | B27: =VLOOKUP(A27,'ITEM LIST'!A:D,3,FALSE) -> NEW MINT, 2.5KG/TRAY | E27: 1 | F27: =VLOOKUP(A27,'ITEM LIST'!A:D,4,FALSE) -> TR | G27: 1312.5 | H27: 1470
A28: FM0337 | B28: =VLOOKUP(A28,'ITEM LIST'!A:D,3,FALSE) -> NEW PISTACHIO, 4.5KG/TRAY | E28: 0.56 | F28: =VLOOKUP(A28,'ITEM LIST'!A:D,4,FALSE) -> TR | G28: 1323 | H28: 1481.76
A29: FM0536 | B29: =VLOOKUP(A29,'ITEM LIST'!A:D,3,FALSE) -> COOKIE DOUGH GELATO, 2.5/TRAY | E29: 1 | F29: =VLOOKUP(A29,'ITEM LIST'!A:D,4,FALSE) -> TR | G29: 1312.5 | H29: 1470
A30: FM0642 | B30: =VLOOKUP(A30,'ITEM LIST'!A:D,3,FALSE) -> TURTLE PIE, 2.5KG/TRAY | E30: 1 | F30: =VLOOKUP(A30,'ITEM LIST'!A:D,4,FALSE) -> TR | G30: 1312.5 | H30: 1470
A31: FM0819 | B31: =VLOOKUP(A31,'ITEM LIST'!A:D,3,FALSE) -> STRAWBERRY GELATO, 2.5 KG TRAY | E31: 1 | F31: =VLOOKUP(A31,'ITEM LIST'!A:D,4,FALSE) -> TR | G31: 1312.5 | H31: 1470
A32: FM0822 | B32: =VLOOKUP(A32,'ITEM LIST'!A:D,3,FALSE) -> CHOCOLATE THERAPY GELATO, 4.5/TRAY | E32: 0.56 | F32: =VLOOKUP(A32,'ITEM LIST'!A:D,4,FALSE) -> TR | G32: 1323 | H32: 1481.76
A33: FM0827 | B33: =VLOOKUP(A33,'ITEM LIST'!A:D,3,FALSE) -> OREO COOKIES N' CREAM, 4.5KG./TRAY | E33: 0.56 | F33: =VLOOKUP(A33,'ITEM LIST'!A:D,4,FALSE) -> TR | G33: 1323 | H33: 1481.76
A34: FM0849 | B34: =VLOOKUP(A34,'ITEM LIST'!A:D,3,FALSE) -> MANGO CREAM PIE 4.5 KG | E34: 0.56 | F34: =VLOOKUP(A34,'ITEM LIST'!A:D,4,FALSE) -> TR | G34: 1188 | H34: 1330.56
A35: FM1132 | B35: =VLOOKUP(A35,'ITEM LIST'!A:D,3,FALSE) -> COFFEE MUDSLIDE GELATO, 2.5KGS./TRAY | E35: 1 | F35: =VLOOKUP(A35,'ITEM LIST'!A:D,4,FALSE) -> TR | G35: 1312.5 | H35: 1470
A36: FM0462 | B36: =VLOOKUP(A36,'ITEM LIST'!A:D,3,FALSE) -> PISTACCHOCOLATO, WHOLE | E36: 8 | F36: =VLOOKUP(A36,'ITEM LIST'!A:D,4,FALSE) -> PC | G36: 3832.5 | H36: 4292.4
A37: FM0533 | B37: =VLOOKUP(A37,'ITEM LIST'!A:D,3,FALSE) -> PISTACCHOCOLATO, CAKE MINI, PC | E37: 4 | F37: =VLOOKUP(A37,'ITEM LIST'!A:D,4,FALSE) -> PC | G37: 1391.25 | H37: 1558.2
A38: FM0566 | B38: =VLOOKUP(A38,'ITEM LIST'!A:D,3,FALSE) -> CASHEW BRITTLE, 15G/PK, PK | E38: 12 | F38: =VLOOKUP(A38,'ITEM LIST'!A:D,4,FALSE) -> PK | G38: 63.104431 | H38: 70.676963
... A66: FM0462 | B66: =VLOOKUP(A66,'ITEM LIST'!A:D,3,FALSE) -> PISTACCHOCOLATO, WHOLE | E66: 8 | F66: =VLOOKUP(A66,'ITEM LIST'!A:D,4,FALSE) -> PC | G66: 3832.5 | H66: 4292.4
B70: Branch: FMM
B72: Week: 5/1/2023
B74: Superceeds Invoice NO: 6533
F75: Total Sales (VAT Incluive) | H75: =SUM(H27:H73) -> 92408.432
H77: 9900.9034
A79: Vatables Sales | H79: =H75-H77 -> 82507.529
A80: VAT
A81: Zero-Rated Sales | F81: =H79 -> 82507.529
A82: VAT-Excempt Sales
F83: =H77 -> 9900.9034 | H83: =F83 -> 9900.9034
H84: =F81*0.01 -> 825.07529
H85: =(H79+H83)-H84 -> 91583.357

Sheet FMM (7)
H15: 45077
A20: Registered Name: | B20: Cara Mia Sales and Services Inc. | H20: WH/OUT/32774, WH/OUT/32795, WH/OUT/32636
A22: TIN: | B22: 009-062-877
A24: Business Address: | B24: 101 Connecticut cor Missouri St. Greenhills San Juan
A26: ITEM CODE | B26: ITEM DESCRIPTION
A27: FM1210 | B27: =VLOOKUP(A27,'ITEM LIST'!A:D,3,FALSE) -> MINI UBE CAKE | E27: 4 | F27: =VLOOKUP(A27,'ITEM LIST'!A:D,4,FALSE) -> PC | G27: 1303.75 | H27: 1460.2
A28: FM1116 | B28: =VLOOKUP(A28,'ITEM LIST'!A:D,3,FALSE) -> STRAWBERRY CAKE, PIECE | E28: 3 | F28: =VLOOKUP(A28,'ITEM LIST'!A:D,4,FALSE) -> PC | G28: 1830.9375 | H28: 2050.65
A29: FM1212 | B29: =VLOOKUP(A29,'ITEM LIST'!A:D,3,FALSE) -> STRAWBERRY, VACUUM PACKED, PK | E29: 3 | F29: =VLOOKUP(A29,'ITEM LIST'!A:D,4,FALSE) -> PK | G29: 317.32097 | H29: 355.39948
A30: FM0594 | B30: =VLOOKUP(A30,'ITEM LIST'!A:D,3,FALSE) -> SEA SALTED HONEY CRUNCH CAKE | E30: 8 | F30: =VLOOKUP(A30,'ITEM LIST'!A:D,4,FALSE) -> PC | G30: 3027.5 | H30: 3390.8
A31: FM1205 | B31: =VLOOKUP(A31,'ITEM LIST'!A:D,3,FALSE) -> UBE GELATO, 2.5 KG/TRAY | E31: 1 | F31: =VLOOKUP(A31,'ITEM LIST'!A:D,4,FALSE) -> TR | G31: 1312.5 | H31: 1470
A32: FM0849 | B32: =VLOOKUP(A32,'ITEM LIST'!A:D,3,FALSE) -> MANGO CREAM PIE 4.5 KG | E32: 0.56 | F32: =VLOOKUP(A32,'ITEM LIST'!A:D,4,FALSE) -> TR | G32: 1188 | H32: 1330.56
A33: FM0827 | B33: =VLOOKUP(A33,'ITEM LIST'!A:D,3,FALSE) -> OREO COOKIES N' CREAM, 4.5KG./TRAY | E33: 0.56 | F33: =VLOOKUP(A33,'ITEM LIST'!A:D,4,FALSE) -> TR | G33: 1323 | H33: 1481.76
A34: FM0822 | B34: =VLOOKUP(A34,'ITEM LIST'!A:D,3,FALSE) -> CHOCOLATE THERAPY GELATO, 4.5/TRAY | E34: 0.56 | F34: =VLOOKUP(A34,'ITEM LIST'!A:D,4,FALSE) -> TR | G34: 1323 | H34: 1481.76
A35: FM1223 | B35: =VLOOKUP(A35,'ITEM LIST'!A:D,3,FALSE) -> MANGO MAGNIFICO CAKE, WHOLE, NEW DESIGN | E35: 10 | F35: =VLOOKUP(A35,'ITEM LIST'!A:D,4,FALSE) -> PC | G35: 4571.875 | H35: 5120.5
A36: FM1281 | B36: =VLOOKUP(A36,'ITEM LIST'!A:D,3,FALSE) -> MINI MANGO MAGNIFICO, PC | E36: 4 | F36: =VLOOKUP(A36,'ITEM LIST'!A:D,4,FALSE) -> PC | G36: 1303.75 | H36: 1460.2
A37: FM1293 | B37: =VLOOKUP(A37,'ITEM LIST'!A:D,3,FALSE) -> SALTED CHOCOLATE SMORES CAKE, NEW, PC | E37: 10 | F37: =VLOOKUP(A37,'ITEM LIST'!A:D,4,FALSE) -> PC | G37: 4571.875 | H37: 5120.5
A38: FM1333 | B38: =VLOOKUP(A38,'ITEM LIST'!A:D,3,FALSE) -> COFFEE CRUNCH, 70 G/PK, PK | E38: 13 | F38: =VLOOKUP(A38,'ITEM LIST'!A:D,4,FALSE) -> PK | G38: 154.7 | H38: 173.264
... A66: FM0822 | B66: =VLOOKUP(A66,'ITEM LIST'!A:D,3,FALSE) -> CHOCOLATE THERAPY GELATO, 4.5/TRAY | E66: 0.56 | F66: =VLOOKUP(A66,'ITEM LIST'!A:D,4,FALSE) -> TR | G66: 1323 | H66: 1481.76
B70: Branch: FMM
B72: Week: 5/1/2023
B74: Superceeds Invoice NO: 6533
F75: Total Sales (VAT Incluive) | H75: =SUM(H27:H73) -> 79909.802
H77: 8561.7645
A79: Vatables Sales | H79: =H75-H77 -> 71348.038
A80: VAT
A81: Zero-Rated Sales | F81: =H79 -> 71348.038
A82: VAT-Excempt Sales
F83: =H77 -> 8561.7645 | H83: =F83 -> 8561.7645
H84: =F81*0.01 -> 713.48038
H85: =(H79+H83)-H84 -> 79196.322

Sheet FMM (8)
H15: 45077
A20: Registered Name: | B20: Cara Mia Sales and Services Inc. | H20: WH/OUT/33097, WH/OUT/33073, WH/OUT/32851, WH/OUT/32774
A22: TIN: | B22: 009-062-877
A24: Business Address: | B24: 101 Connecticut cor Missouri St. Greenhills San Juan
A26: ITEM CODE | B26: ITEM DESCRIPTION
A27: FM0326 | B27: =VLOOKUP(A27,'ITEM LIST'!A:D,3,FALSE) -> NEW MINT, 2.5KG/TRAY | E27: 1 | F27: =VLOOKUP(A27,'ITEM LIST'!A:D,4,FALSE) -> TR | G27: 1312.5 | H27: 1470
A28: FM1333 | B28: =VLOOKUP(A28,'ITEM LIST'!A:D,3,FALSE) -> COFFEE CRUNCH, 70 G/PK, PK | E28: 9 | F28: =VLOOKUP(A28,'ITEM LIST'!A:D,4,FALSE) -> PK | G28: 107.1 | H28: 119.952
A29: FM1210 | B29: =VLOOKUP(A29,'ITEM LIST'!A:D,3,FALSE) -> MINI UBE CAKE | E29: 8 | F29: =VLOOKUP(A29,'ITEM LIST'!A:D,4,FALSE) -> PC | G29: 2607.5 | H29: 2920.4
A30: FM0594 | B30: =VLOOKUP(A30,'ITEM LIST'!A:D,3,FALSE) -> SEA SALTED HONEY CRUNCH CAKE | E30: 10 | F30: =VLOOKUP(A30,'ITEM LIST'!A:D,4,FALSE) -> PC | G30: 3784.375 | H30: 4238.5
A31: FM0376 | B31: =VLOOKUP(A31,'ITEM LIST'!A:D,3,FALSE) -> BLANK HAPPY BIRTHDAY LABEL, 24PCS/BX | E31: 4 | F31: =VLOOKUP(A31,'ITEM LIST'!A:D,4,FALSE) -> BX | G31: 621.98453 | H31: 696.62267
A32: FM1334 | B32: =VLOOKUP(A32,'ITEM LIST'!A:D,3,FALSE) -> CHOCOLATE JAVA CAKE, PC | E32: 10 | F32: =VLOOKUP(A32,'ITEM LIST'!A:D,4,FALSE) -> PC | G32: 4353.125 | H32: 4875.5
A33: FM1223 | B33: =VLOOKUP(A33,'ITEM LIST'!A:D,3,FALSE) -> MANGO MAGNIFICO CAKE, WHOLE, NEW DESIGN | E33: 10 | F33: =VLOOKUP(A33,'ITEM LIST'!A:D,4,FALSE) -> PC | G33: 4571.875 | H33: 5120.5
A34: FM1210 | B34: =VLOOKUP(A34,'ITEM LIST'!A:D,3,FALSE) -> MINI UBE CAKE | E34: 4 | F34: =VLOOKUP(A34,'ITEM LIST'!A:D,4,FALSE) -> PC | G34: 1303.75 | H34: 1460.2
A35: FM1175 | B35: =VLOOKUP(A35,'ITEM LIST'!A:D,3,FALSE) -> UBE CAKE, PC | E35: 22 | F35: =VLOOKUP(A35,'ITEM LIST'!A:D,4,FALSE) -> PC | G35: 10058.125 | H35: 11265.1
A36: FM0846 | B36: =VLOOKUP(A36,'ITEM LIST'!A:D,3,FALSE) -> SEA SALTED CRUNCH 140 GM | E36: 10 | F36: =VLOOKUP(A36,'ITEM LIST'!A:D,4,FALSE) -> PK | G36: 131.33 | H36: 147.0896
A37: FM0565 | B37: =VLOOKUP(A37,'ITEM LIST'!A:D,3,FALSE) -> MIDNIGHT DREAM CAKE, PC | E37: 12 | F37: =VLOOKUP(A37,'ITEM LIST'!A:D,4,FALSE) -> PC | G37: 5591.25 | H37: 6262.2
A38: FM0827 | B38: =VLOOKUP(A38,'ITEM LIST'!A:D,3,FALSE) -> OREO COOKIES N' CREAM, 4.5KG./TRAY | E38: 0.56 | F38: =VLOOKUP(A38,'ITEM LIST'!A:D,4,FALSE) -> TR | G38: 1323 | H38: 1481.76
... A66: FM1120 | B66: =VLOOKUP(A66,'ITEM LIST'!A:D,3,FALSE) -> MIDNIGHT DREAM CAKE, WHOLE, MINI | E66: 4 | F66: =VLOOKUP(A66,'ITEM LIST'!A:D,4,FALSE) -> PC | G66: 1303.75 | H66: 1460.2
B70: Branch: FMM
B72: Week: 5/1/2023
B74: Superceeds Invoice NO: 6533
F75: Total Sales (VAT Incluive) | H75: =SUM(H27:H73) -> 97506.056
H77: 10447.077
A79: Vatables Sales | H79: =H75-H77 -> 87058.979
A80: VAT
A81: Zero-Rated Sales | F81: =H79 -> 87058.979
A82: VAT-Excempt Sales
F83: =H77 -> 10447.077 | H83: =F83 -> 10447.077
H84: =F81*0.01 -> 870.58979
H85: =(H79+H83)-H84 -> 96635.467

Sheet FMM (9)
H15: 45077
A20: Registered Name: | B20: Cara Mia Sales and Services Inc. | H20: WH/OUT/33211, WH/OUT/33073, WH/OUT/33097
A22: TIN: | B22: 009-062-877
A24: Business Address: | B24: 101 Connecticut cor Missouri St. Greenhills San Juan
A26: ITEM CODE | B26: ITEM DESCRIPTION
A27: FM1212 | B27: =VLOOKUP(A27,'ITEM LIST'!A:D,3,FALSE) -> STRAWBERRY, VACUUM PACKED, PK | E27: 1 | F27: =VLOOKUP(A27,'ITEM LIST'!A:D,4,FALSE) -> PK | G27: 317.32097 | H27: 355.39948
A28: FM0594 | B28: =VLOOKUP(A28,'ITEM LIST'!A:D,3,FALSE) -> SEA SALTED HONEY CRUNCH CAKE | E28: 9 | F28: =VLOOKUP(A28,'ITEM LIST'!A:D,4,FALSE) -> PC | G28: 3784.375 | H28: 4238.5
A29: FM0566 | B29: =VLOOKUP(A29,'ITEM LIST'!A:D,3,FALSE) -> CASHEW BRITTLE, 15G/PK, PK | E29: 8 | F29: =VLOOKUP(A29,'ITEM LIST'!A:D,4,FALSE) -> PK | G29: 63.104431 | H29: 70.676963
A30: FM0827 | B30: =VLOOKUP(A30,'ITEM LIST'!A:D,3,FALSE) -> OREO COOKIES N' CREAM, 4.5KG./TRAY | E30: 10 | F30: =VLOOKUP(A30,'ITEM LIST'!A:D,4,FALSE) -> TR | G30: 1323 | H30: 1481.76
A31: FM0326 | B31: =VLOOKUP(A31,'ITEM LIST'!A:D,3,FALSE) -> NEW MINT, 2.5KG/TRAY | E31: 4 | F31: =VLOOKUP(A31,'ITEM LIST'!A:D,4,FALSE) -> TR | G31: 1312.5 | H31: 1470
A32: FM0376 | B32: =VLOOKUP(A32,'ITEM LIST'!A:D,3,FALSE) -> BLANK HAPPY BIRTHDAY LABEL, 24PCS/BX | E32: 10 | F32: =VLOOKUP(A32,'ITEM LIST'!A:D,4,FALSE) -> BX | G32: 310.99226 | H32: 348.31134
A33: FM1210 | B33: =VLOOKUP(A33,'ITEM LIST'!A:D,3,FALSE) -> MINI UBE CAKE | E33: 10 | F33: =VLOOKUP(A33,'ITEM LIST'!A:D,4,FALSE) -> PC | G33: 1303.75 | H33: 1460.2
A34: FM1118 | B34: =VLOOKUP(A34,'ITEM LIST'!A:D,3,FALSE) -> CASHEW BRITTLE, 10 GRAMS PER PACK | E34: 4 | F34: =VLOOKUP(A34,'ITEM LIST'!A:D,4,FALSE) -> PK | G34: 14.023207 | H34: 15.705992
A35: FM0846 | B35: =VLOOKUP(A35,'ITEM LIST'!A:D,3,FALSE) -> SEA SALTED CRUNCH 140 GM | E35: 22 | F35: =VLOOKUP(A35,'ITEM LIST'!A:D,4,FALSE) -> PK | G35: 131.33 | H35: 147.0896
A36: FM0337 | B36: =VLOOKUP(A36,'ITEM LIST'!A:D,3,FALSE) -> NEW PISTACHIO, 4.5KG/TRAY | E36: 10 | F36: =VLOOKUP(A36,'ITEM LIST'!A:D,4,FALSE) -> TR | G36: 1323 | H36: 1481.76
A37: FM0533 | B37: =VLOOKUP(A37,'ITEM LIST'!A:D,3,FALSE) -> PISTACCHOCOLATO, CAKE MINI, PC | E37: 12 | F37: =VLOOKUP(A37,'ITEM LIST'!A:D,4,FALSE) -> PC | G37: 1391.25 | H37: 1558.2
A38: FM0536 | B38: =VLOOKUP(A38,'ITEM LIST'!A:D,3,FALSE) -> COOKIE DOUGH GELATO, 2.5/TRAY | E38: 0.56 | F38: =VLOOKUP(A38,'ITEM LIST'!A:D,4,FALSE) -> TR | G38: 1312.5 | H38: 1470
... A66: FM1116 | B66: =VLOOKUP(A66,'ITEM LIST'!A:D,3,FALSE) -> STRAWBERRY CAKE, PIECE | E66: 4 | F66: =VLOOKUP(A66,'ITEM LIST'!A:D,4,FALSE) -> PC | G66: 2441.25 | H66: 2734.2
B70: Branch: FMM
B72: Week: 5/1/2023
B74: Superceeds Invoice NO: 6533
F75: Total Sales (VAT Incluive) | H75: =SUM(H27:H73) -> 101818.01
H77: 10909.072
A79: Vatables Sales | H79: =H75-H77 -> 90908.937
A80: VAT
A81: Zero-Rated Sales | F81: =H79 -> 90908.937
A82: VAT-Excempt Sales
F83: =H77 -> 10909.072 | H83: =F83 -> 10909.072
H84: =F81*0.01 -> 909.08937
H85: =(H79+H83)-H84 -> 100908.92

Sheet FMM (10)
H15: 45077
A20: Registered Name: | B20: Cara Mia Sales and Services Inc. | H20: WH/OUT/33314, WH/IN/2592, WH/OUT/33244, WH/OUT/33211
A22: TIN: | B22: 009-062-877
A24: Business Address: | B24: 101 Connecticut cor Missouri St. Greenhills San Juan
A26: ITEM CODE | B26: ITEM DESCRIPTION
A27: FM1212 | B27: =VLOOKUP(A27,'ITEM LIST'!A:D,3,FALSE) -> STRAWBERRY, VACUUM PACKED, PK | E27: 4 | F27: =VLOOKUP(A27,'ITEM LIST'!A:D,4,FALSE) -> PK | G27: 423.09462 | H27: 473.86598
A28: FM0566 | B28: =VLOOKUP(A28,'ITEM LIST'!A:D,3,FALSE) -> CASHEW BRITTLE, 15G/PK, PK | E28: 12 | F28: =VLOOKUP(A28,'ITEM LIST'!A:D,4,FALSE) -> PK | G28: 63.104431 | H28: 70.676963
A29: FM0462 | B29: =VLOOKUP(A29,'ITEM LIST'!A:D,3,FALSE) -> PISTACCHOCOLATO, WHOLE | E29: 10 | F29: =VLOOKUP(A29,'ITEM LIST'!A:D,4,FALSE) -> PC | G29: 4790.625 | H29: 5365.5
A30: FM0822 | B30: =VLOOKUP(A30,'ITEM LIST'!A:D,3,FALSE) -> CHOCOLATE THERAPY GELATO, 4.5/TRAY | E30: 1 | F30: =VLOOKUP(A30,'ITEM LIST'!A:D,4,FALSE) -> TR | G30: 2362.5 | H30: 2646
A31: FM0819 | B31: =VLOOKUP(A31,'ITEM LIST'!A:D,3,FALSE) -> STRAWBERRY GELATO, 2.5 KG TRAY | E31: 1 | F31: =VLOOKUP(A31,'ITEM LIST'!A:D,4,FALSE) -> TR | G31: 1312.5 | H31: 1470
A32: FM0536 | B32: =VLOOKUP(A32,'ITEM LIST'!A:D,3,FALSE) -> COOKIE DOUGH GELATO, 2.5/TRAY | E32: 1 | F32: =VLOOKUP(A32,'ITEM LIST'!A:D,4,FALSE) -> TR | G32: 1312.5 | H32: 1470
A33: FM1214 | B33: =VLOOKUP(A33,'ITEM LIST'!A:D,3,FALSE) -> RED GLAZE, 100G/PK | E33: 1 | F33: =VLOOKUP(A33,'ITEM LIST'!A:D,4,FALSE) -> PK | G33: 23.470077 | H33: 26.286486
A34: FM0376 | B34: =VLOOKUP(A34,'ITEM LIST'!A:D,3,FALSE) -> BLANK HAPPY BIRTHDAY LABEL, 24PCS/BX | E34: 2 | F34: =VLOOKUP(A34,'ITEM LIST'!A:D,4,FALSE) -> BX | G34: 310.99226 | H34: 348.31134
A35: FM0365 | B35: =VLOOKUP(A35,'ITEM LIST'!A:D,3,FALSE) -> STRAWBERRY FROZEN, 150G / PACK | E35: 1 | F35: =VLOOKUP(A35,'ITEM LIST'!A:D,4,FALSE) -> PK | G35: 35.58 | H35: 39.8496
A36: CM0001 | B36: =VLOOKUP(A36,'ITEM LIST'!A:D,3,FALSE) -> CLING WRAP, 30 METERS PER ROLL | E36: 2 | F36: =VLOOKUP(A36,'ITEM LIST'!A:D,4,FALSE) -> RL | G36: 492.867 | H36: 552.01104
A37: CM0003 | B37: =VLOOKUP(A37,'ITEM LIST'!A:D,3,FALSE) -> DISPOSABLE, PLASTIC GLOVES, LARGE, 100 PCS XPACK | E37: 5 | F37: =VLOOKUP(A37,'ITEM LIST'!A:D,4,FALSE) -> PK | G37: 256.68 | H37: 287.4816
A38: CM0024 | B38: =VLOOKUP(A38,'ITEM LIST'!A:D,3,FALSE) -> CLEANING, YELLOW SCRUB SPONGE, 2 in 1, 3in x 3.75in | E38: 2 | F38: =VLOOKUP(A38,'ITEM LIST'!A:D,4,FALSE) -> PC | G38: 65.987 | H38: 73.90544
... A66: FM1118 | B66: =VLOOKUP(A66,'ITEM LIST'!A:D,3,FALSE) -> CASHEW BRITTLE, 10 GRAMS PER PACK | E66: 7 | F66: =VLOOKUP(A66,'ITEM LIST'!A:D,4,FALSE) -> PK | G66: 24.540612 | H66: 27.485486
B70: Branch: FMM
B72: Week: 5/1/2023
B74: Superceeds Invoice NO: 6533
F75: Total Sales (VAT Incluive) | H75: =SUM(H27:H73) -> 77839.279
H77: 8339.9228
A79: Vatables Sales | H79: =H75-H77 -> 69499.356
A80: VAT
A81: Zero-Rated Sales | F81: =H79 -> 69499.356
A82: VAT-Excempt Sales
F83: =H77 -> 8339.9228 | H83: =F83 -> 8339.9228
H84: =F81*0.01 -> 694.99356
H85: =(H79+H83)-H84 -> 77144.286

Sheet FMM (11)
H15: 45077
A20: Registered Name: | B20: Cara Mia Sales and Services Inc.
A22: TIN: | B22: 009-062-877
A24: Business Address: | B24: 101 Connecticut cor Missouri St. Greenhills San Juan
A26: ITEM CODE | B26: ITEM DESCRIPTION
A27: FM0594 | B27: =VLOOKUP(A27,'ITEM LIST'!A:D,3,FALSE) -> SEA SALTED HONEY CRUNCH CAKE | E27: 15 | F27: =VLOOKUP(A27,'ITEM LIST'!A:D,4,FALSE) -> PC | G27: 5676.5625 | H27: 6357.75
A28: FM0566 | B28: =VLOOKUP(A28,'ITEM LIST'!A:D,3,FALSE) -> CASHEW BRITTLE, 15G/PK, PK | E28: 12 | F28: =VLOOKUP(A28,'ITEM LIST'!A:D,4,FALSE) -> PK | G28: 63.104431 | H28: 70.676963
A29: FM1132 | B29: =VLOOKUP(A29,'ITEM LIST'!A:D,3,FALSE) -> COFFEE MUDSLIDE GELATO, 2.5KGS./TRAY | E29: 1 | F29: =VLOOKUP(A29,'ITEM LIST'!A:D,4,FALSE) -> TR | G29: 1312.5 | H29: 1470
A30: FM0849 | B30: =VLOOKUP(A30,'ITEM LIST'!A:D,3,FALSE) -> MANGO CREAM PIE 4.5 KG | E30: 0.56 | F30: =VLOOKUP(A30,'ITEM LIST'!A:D,4,FALSE) -> TR | G30: 1188 | H30: 1330.56
A31: FM0827 | B31: =VLOOKUP(A31,'ITEM LIST'!A:D,3,FALSE) -> OREO COOKIES N' CREAM, 4.5KG./TRAY | E31: 0.56 | F31: =VLOOKUP(A31,'ITEM LIST'!A:D,4,FALSE) -> TR | G31: 1323 | H31: 1481.76
A32: FM0822 | B32: =VLOOKUP(A32,'ITEM LIST'!A:D,3,FALSE) -> CHOCOLATE THERAPY GELATO, 4.5/TRAY | E32: 1 | F32: =VLOOKUP(A32,'ITEM LIST'!A:D,4,FALSE) -> TR | G32: 2362.5 | H32: 2646
A33: CM0003 | B33: =VLOOKUP(A33,'ITEM LIST'!A:D,3,FALSE) -> DISPOSABLE, PLASTIC GLOVES, LARGE, 100 PCS XPACK | E33: 5 | F33: =VLOOKUP(A33,'ITEM LIST'!A:D,4,FALSE) -> PK | G33: 256.68 | H33: 287.4816
A34: PM0062 | B34: =VLOOKUP(A34,'ITEM LIST'!A:D,3,FALSE) -> DISPOSABLE PAPER CUP, W/PRINT, 4OZ, PC | E34: 200 | F34: =VLOOKUP(A34,'ITEM LIST'!A:D,4,FALSE) -> PC | G34: 296.7 | H34: 332.304
A35: PM0181 | B35: =VLOOKUP(A35,'ITEM LIST'!A:D,3,FALSE) -> PLASTIC, TUB & LID, GELATO, 1Liter | E35: 40 | F35: =VLOOKUP(A35,'ITEM LIST'!A:D,4,FALSE) -> SET | G35: 632.96 | H35: 708.9152
A36: PM0158 | B36: =VLOOKUP(A36,'ITEM LIST'!A:D,3,FALSE) -> PAPER, BAG, KRAFT#2, CARAMIA, 70GSM | E36: 60 | F36: =VLOOKUP(A36,'ITEM LIST'!A:D,4,FALSE) -> PC | G36: 286.35 | H36: 320.712
A37: PM0159 | B37: =VLOOKUP(A37,'ITEM LIST'!A:D,3,FALSE) -> PLASTIC, CONTAINER, PET C-302, 294X150X48MM | E37: 100 | F37: =VLOOKUP(A37,'ITEM LIST'!A:D,4,FALSE) -> PC | G37: 462.3 | H37: 517.776
A38: PM0063 | B38: =VLOOKUP(A38,'ITEM LIST'!A:D,3,FALSE) -> DISPOSABLE PAPER CUP, W/PRINT, 8.79OZ, PC | E38: 200 | F38: =VLOOKUP(A38,'ITEM LIST'!A:D,4,FALSE) -> PC | G38: 328.9 | H38: 368.368
... A48: FM1358 | B48: =VLOOKUP(A48,'ITEM LIST'!A:D,3,FALSE) -> MANGO CREAM PIE ver.1, PC | E48: 2 | F48: =VLOOKUP(A48,'ITEM LIST'!A:D,4,FALSE) -> PC | G48: 1045.62 | H48: 1171.0944
B70: Branch: FMM
B72: Week: 5/1/2023
B74: Superceeds Invoice NO: 6533
F75: Total Sales (VAT Incluive) | H75: =SUM(H27:H73) -> 22979.41
H77: 2462.0797
A79: Vatables Sales | H79: =H75-H77 -> 20517.331
A80: VAT
A81: Zero-Rated Sales | F81: =H79 -> 20517.331
A82: VAT-Excempt Sales
F83: =H77 -> 2462.0797 | H83: =F83 -> 2462.0797
H84: =F81*0.01 -> 205.17331
H85: =(H79+H83)-H84 -> 22774.237

Sheet Sheet1
K11: wh/out
H20: WH/OUT/31850, WH/OUT/31870, WH/OUT/31836, WH/OUT/32077
H21: CARA MIA SALES AND SERVICES INC.
H22: CARA MIA SALES AND SERVICES INC.
H23: CARA MIA SALES AND SERVICES INC.
H24: CARA MIA SALES AND SERVICES INC.
H25: CARA MIA SALES AND SERVICES INC.
E27: DR Reference
G28: Posting Group | H28: Transfer Price
E29: WH/OUT/31015 | G29: FM | H29: 1312.5
E30: WH/OUT/31015 | G30: FM | H30: 1312.5
E31: WH/OUT/31015 | G31: FM | H31: 1312.5
E32: WH/OUT/31015 | G32: FM | H32: 46.009273
E33: WH/OUT/31015 | G33: FM | H33: 155.49613
E34: WH/OUT/31015 | G34: FM | H34: 2362.5
E35: WH/OUT/31015 | G35: FM | H35: 1312.5
E36: WH/OUT/31015 | G36: FM | H36: 2362.5
E37: WH/OUT/31015 | G37: FM | H37: 162.69
E38: WH/OUT/31015 | G38: FM | H38: 2362.5
E39: WH/OUT/31015 | G39: FM | H39: 2362.5
E40: WH/OUT/31015 | G40: FM | H40: 1312.5
... E65: WH/OUT/31230 | G65: FM | H65: 105.77366
B70: Branch: LCT
B74: Superceeds Invoice NO: 6533
F77: vat | H77: 11.42
H79: =H75-H77 -> -11.42

Sheet ITEM LIST
A1: CODE | B1: POSTING GROUP | C1: DESCRIPTION | D1: UOM
A2: CM0001 | B2: FS | C2: CLING WRAP, 30 METERS PER ROLL | D2: RL
A3: CM0002 | B3: FS | C3: BAG, GARBAGE, CLEAR, 40" X 37" ( 45 MICRONS ) | D3: PC
A4: CM0003 | B4: FS | C4: DISPOSABLE, PLASTIC GLOVES, LARGE, 100 PCS XPACK | D4: PK
A5: CM0004 | B5: FS | C5: BAG, LDPE, 3 X 10, WHITE HORSE | D5: PC
A6: CM0005 | B6: FS | C6: PAPER, GREASEPROOF SHEET, 24” X 36", 34GSM 480PC/REAM | D6: RM
A7: CM0007 | B7: FS | C7: DRINKING STRAW,PS, RED, 1000 PCS X 1 PACK(1KG) | D7: PK
A8: CM0009 | B8: FS | C8: TOOTHPICK, INDIVIDUALLY WRAPPED, 1000 PC/PK, PK | D8: PK
A9: CM0011 | B9: FS | C9: DISPOSABLE PLASTIC SPOON, BLACK, 25 PCS X 100 PK X 1CS | D9: PC
A10: CM0012 | B10: FS | C10: DISPOSABLE PLASTIC FORK, BLACK, 25 PCS X 100 PK X 1 CS | D10: PC
A11: CM0013 | B11: FUEL | C11: GAS - LPG 50KG (GASUL) | D11: TK
A12: CM0014 | B12: FS | C12: TISSUE, SCOTT BATHROOM HYGENIC 48 PK X 1CS | D12: PK
... A428: PM0186 | B428: PM | C428: STICKER, CARAMIA HEART-SHAPE W/ PLASTIC LAM, 1.45”x1.75” | D428: PC
A429: PM0187 | B429: PM | C429: VACANT
A430: PM0188 | B430: PM | C430: STYRO ROUND, 6IN DIA x 3IN THICK | D430: PC
A431: PM0189 | B431: PM | C431: INSULATED FOAM, POUCH, TUB, 11x10”x6in (overlap) | D431: PC
A432: PM0190 | B432: PM | C432: INSULATED FOAM, POUCH, PINT, 8x10”x 5in (overlap) | D432: PC
A433: PM0191 | B433: PM | C433: DELIVERY THERMAL BAG, BLACK W/ AMICI LOGO | D433: PC
A434: PM0192 | B434: PM | C434: TRAY, ALUMINUM 3011MH,228mm(TO)x165mm(BO)dia x 27mm(Depth) | D434: PC
A435: PM0193 | B435: PM | C435: ECO BAG,NON-WOVEN, PINK W/ PRINT, 30Lx28.5Wx33Hcm w/ piping | D435: PC
A436: PM0194 | B436: PM | C436: TAPE,2inx10m (Double adhesive-for MCP) | D436: PC
A437: PM0195 | B437: PM | C437: POUCH,LAMPAPER/PE,S-Gusset,50gsm,80Lx150Hx56Wmm | D437: PC
A438: PM0196 | B438: PM | C438: TAPE,1inx10m (Double adhesive-for MCP) | D438: PC
A439: PM0197 | B439: PM | C439: STYRO, RECTANGULAR, 125MMx330MMx45MM | D439: PC
A440: PM0198 | B440: PM | C440: GREASEPROOF SHEET , ORANGE, 36inx24in, 10’S/pck | D440: PCK
A441: PM0199 | B441: PM | C441: OPP SHEET, PLAIN,115mmWx275mmLx30mic | D441: PC
... A812: RM0454 | B812: RM | C812: CHOCOLATE, DARK INTENSE COMPOUND BLOCK VAN HOUTEN | D812: KG
A813: RM0455 | B813: RM | C813: VAN HOUTEN INTENSE DARK CHOCOLATE, 1 KG/BLOCK, KG
A814: RM0456 | B814: RM | C814: NUTS, HAZELNUT WHOLE | D814: KG
A815: RM0457 | B815: RM | C815: CHOCOLATE, FERRERO ROCHER | D815: KG
A816: RM0458 | B816: RM | C816: VEGETABLE, CILANTRO | D816: KG
A817: RM0459 | B817: RM | C817: COLOURING, CHOCO BROWN LIQUID | D817: LT
A818: RM0460 | B818: RM | C818: BISCUIT, FEUILLETINE FINE CRUMBLE,CALLEBAUT, 1/2.5KG | D818: KG
A819: RM0461 | B819: RM | C819: NUTS, ALMOND WHOLE RAW,1/1KG | D819: KG
A820: RM0462 | B820: RM | C820: CHOCOLATE, VAN HOUTEN SEMI SWEET DARK COMPOUND | D820: KG
A821: RM0463 | B821: RM | C821: SEASONING, CAJUN | D821: KG
A822: RM0464 | B822: RM | C822: PEACH HALVES IN SYRUP | D822: KG
A823: RM0465 | B823: RM | C823: MALTESERS | D823: KG
A824: RM0466 | B824: RM | C824: FRUTAFIT TEX INULIN | D824: KG
A825: RM0467 | B825: RM | C825: DISTILLED GLYCERIN MONOSTEARATE (DMG95 | D825: KG
...
